 * Serving Flask app "api" (lazy loading)
 * Environment: production
   WARNING: This is a development server. Do not use it in a production deployment.
   Use a production WSGI server instead.
 * Debug mode: on
 * Running on http://0.0.0.0:3404/ (Press CTRL+C to quit)
 * Restarting with stat
 * Debugger is active!
 * Debugger PIN: 173-965-101
127.0.0.1 - - [15/Oct/2020 17:21:41] "GET / HTTP/1.1" 404 -
127.0.0.1 - - [15/Oct/2020 17:21:42] "GET /favicon.ico HTTP/1.1" 200 -
127.0.0.1 - - [15/Oct/2020 17:21:54] "GET / HTTP/1.1" 404 -
127.0.0.1 - - [15/Oct/2020 17:21:59] "GET / HTTP/1.1" 404 -
127.0.0.1 - - [15/Oct/2020 17:22:06] "GET /api HTTP/1.1" 404 -
 * Detected change in '/mnt/c/work/p101/annoq/annoq-api/setup_es.py', reloading
 * Restarting with stat
Traceback (most recent call last):
  File "/mnt/c/work/p101/annoq/annoq-api/venv/lib/python3.8/site-packages/urllib3/connection.py", line 156, in _new_conn
    conn = connection.create_connection(
  File "/mnt/c/work/p101/annoq/annoq-api/venv/lib/python3.8/site-packages/urllib3/util/connection.py", line 84, in create_connection
    raise err
  File "/mnt/c/work/p101/annoq/annoq-api/venv/lib/python3.8/site-packages/urllib3/util/connection.py", line 74, in create_connection
    sock.connect(sa)
ConnectionRefusedError: [Errno 111] Connection refused

During handling of the above exception, another exception occurred:

Traceback (most recent call last):
  File "/mnt/c/work/p101/annoq/annoq-api/venv/lib/python3.8/site-packages/elasticsearch/connection/http_urllib3.py", line 237, in perform_request
    response = self.pool.urlopen(
  File "/mnt/c/work/p101/annoq/annoq-api/venv/lib/python3.8/site-packages/urllib3/connectionpool.py", line 719, in urlopen
    retries = retries.increment(
  File "/mnt/c/work/p101/annoq/annoq-api/venv/lib/python3.8/site-packages/urllib3/util/retry.py", line 376, in increment
    raise six.reraise(type(error), error, _stacktrace)
  File "/mnt/c/work/p101/annoq/annoq-api/venv/lib/python3.8/site-packages/urllib3/packages/six.py", line 735, in reraise
    raise value
  File "/mnt/c/work/p101/annoq/annoq-api/venv/lib/python3.8/site-packages/urllib3/connectionpool.py", line 665, in urlopen
    httplib_response = self._make_request(
  File "/mnt/c/work/p101/annoq/annoq-api/venv/lib/python3.8/site-packages/urllib3/connectionpool.py", line 387, in _make_request
    conn.request(method, url, **httplib_request_kw)
  File "/usr/lib/python3.8/http/client.py", line 1240, in request
    self._send_request(method, url, body, headers, encode_chunked)
  File "/usr/lib/python3.8/http/client.py", line 1286, in _send_request
    self.endheaders(body, encode_chunked=encode_chunked)
  File "/usr/lib/python3.8/http/client.py", line 1235, in endheaders
    self._send_output(message_body, encode_chunked=encode_chunked)
  File "/usr/lib/python3.8/http/client.py", line 1006, in _send_output
    self.send(msg)
  File "/usr/lib/python3.8/http/client.py", line 946, in send
    self.connect()
  File "/mnt/c/work/p101/annoq/annoq-api/venv/lib/python3.8/site-packages/urllib3/connection.py", line 184, in connect
    conn = self._new_conn()
  File "/mnt/c/work/p101/annoq/annoq-api/venv/lib/python3.8/site-packages/urllib3/connection.py", line 168, in _new_conn
    raise NewConnectionError(
urllib3.exceptions.NewConnectionError: <urllib3.connection.HTTPConnection object at 0x7f420a1457c0>: Failed to establish a new connection: [Errno 111] Connection refused

During handling of the above exception, another exception occurred:

Traceback (most recent call last):
  File "/mnt/c/work/p101/annoq/annoq-api/api.py", line 17, in <module>
    tree_list = init_tree_list()
  File "/mnt/c/work/p101/annoq/annoq-api/tree.py", line 118, in init_tree_list
    all_mapping = es.indices.get_mapping()
  File "/mnt/c/work/p101/annoq/annoq-api/venv/lib/python3.8/site-packages/elasticsearch/client/utils.py", line 84, in _wrapped
    return func(*args, params=params, **kwargs)
  File "/mnt/c/work/p101/annoq/annoq-api/venv/lib/python3.8/site-packages/elasticsearch/client/indices.py", line 388, in get_mapping
    return self.transport.perform_request(
  File "/mnt/c/work/p101/annoq/annoq-api/venv/lib/python3.8/site-packages/elasticsearch/transport.py", line 351, in perform_request
    status, headers_response, data = connection.perform_request(
  File "/mnt/c/work/p101/annoq/annoq-api/venv/lib/python3.8/site-packages/elasticsearch/connection/http_urllib3.py", line 250, in perform_request
    raise ConnectionError("N/A", str(e), e)
elasticsearch.exceptions.ConnectionError: ConnectionError(<urllib3.connection.HTTPConnection object at 0x7f420a1457c0>: Failed to establish a new connection: [Errno 111] Connection refused) caused by: NewConnectionError(<urllib3.connection.HTTPConnection object at 0x7f420a1457c0>: Failed to establish a new connection: [Errno 111] Connection refused)
